Workbook

Sheet Diario Completo Leo
A1: Fecha | B1: Etapa | C1: Balance Inicial | D1: Resultado | E1: Operación | F1: Estrategia | G1: Ajuste 1 | H1: Ajuste 2 | I1: Ajuste 3 | J1: Ajuste 4 | K1: Balance Final | L1: Abono/Retiro | M1: % día | N1: % Acumulado | O1: Observaciones | P1: Concepto
A2: 46307 | B2: Semilla | C2: 520.02 | D2: TP | E2: SELL | F2: 4.26 | K2: =Tabla13[[#This Row],[Balance Inicial ]]+Tabla13[[#This Row],[Estrategia]]+Tabla13[[#This Row],[Ajuste 1]]+Tabla13[[#This Row],[Ajuste 2]]+Tabla13[[#This Row],[Ajuste 3]]+Tabla13[[#This Row],[Ajuste 4]] -> 524.28 | M2: =(Tabla13[[#This Row],[Estrategia]]+Tabla13[[#This Row],[Ajuste 1]]+Tabla13[[#This Row],[Ajuste 2]]+Tabla13[[#This Row],[Ajuste 3]]+Tabla13[[#This Row],[Ajuste 4]])/Tabla13[[#This Row],[Balance Inicial ]]*100 -> 0.81919926 | N2: 0.82 | O2: Mercado con ruido, se ingresa a la operación asegurando un 50% y dejando correr, cierra SL positivo, se devuelve precio a Compra | P2: Proteger primero: con ruido, asegurar el 50% y dejar correr; el mercado paga después.
A3: 46308 | B3: Semilla | C3: =K2+L2 -> 524.28 | D3: SL | E3: SELL | F3: 0 | K3: =Tabla13[[#This Row],[Balance Inicial ]]+Tabla13[[#This Row],[Estrategia]]+Tabla13[[#This Row],[Ajuste 1]]+Tabla13[[#This Row],[Ajuste 2]]+Tabla13[[#This Row],[Ajuste 3]]+Tabla13[[#This Row],[Ajuste 4]] -> 524.28 | M3: =(Tabla13[[#This Row],[Estrategia]]+Tabla13[[#This Row],[Ajuste 1]]+Tabla13[[#This Row],[Ajuste 2]]+Tabla13[[#This Row],[Ajuste 3]]+Tabla13[[#This Row],[Ajuste 4]])/Tabla13[[#This Row],[Balance Inicial ]]*100 -> 0 | N3: =Tabla13[[#This Row],[% día]]+N2 -> 0.82 | O3: Ruido en Ventas, se asegura entrada inmediatamente queda en positivo se devuelve a SL | P3: Salir en cero también es ganar: en el ruido se asegura de inmediato y, si el precio se devuelve, la gestión ya hizo su trabajo.
A4: 46309 | B4: Semilla | C4: =K3+L3 -> 524.28 | D4: SL | E4: SELL | K4: =Tabla13[[#This Row],[Balance Inicial ]]+Tabla13[[#This Row],[Estrategia]]+Tabla13[[#This Row],[Ajuste 1]]+Tabla13[[#This Row],[Ajuste 2]]+Tabla13[[#This Row],[Ajuste 3]]+Tabla13[[#This Row],[Ajuste 4]] -> 524.28 | M4: =(Tabla13[[#This Row],[Estrategia]]+Tabla13[[#This Row],[Ajuste 1]]+Tabla13[[#This Row],[Ajuste 2]]+Tabla13[[#This Row],[Ajuste 3]]+Tabla13[[#This Row],[Ajuste 4]])/Tabla13[[#This Row],[Balance Inicial ]]*100 -> 0 | N4: =Tabla13[[#This Row],[% día]]+N3 -> 0.82 | O4: PPA 300, SL Ahorrado | P4: No operar es una operación: con PPA 300 la señal pierde su ventaja y el SL ahorrado es capital protegido.
A5: 46310 | B5: Semilla | C5: =K4+L4 -> 524.28 | D5: SL | E5: SELL | K5: =Tabla13[[#This Row],[Balance Inicial ]]+Tabla13[[#This Row],[Estrategia]]+Tabla13[[#This Row],[Ajuste 1]]+Tabla13[[#This Row],[Ajuste 2]]+Tabla13[[#This Row],[Ajuste 3]]+Tabla13[[#This Row],[Ajuste 4]] -> 524.28 | M5: =(Tabla13[[#This Row],[Estrategia]]+Tabla13[[#This Row],[Ajuste 1]]+Tabla13[[#This Row],[Ajuste 2]]+Tabla13[[#This Row],[Ajuste 3]]+Tabla13[[#This Row],[Ajuste 4]])/Tabla13[[#This Row],[Balance Inicial ]]*100 -> 0 | N5: =Tabla13[[#This Row],[% día]]+N4 -> 0.82 | O5: PPA 135, SL Ahorrado | P5: La constancia en la regla: segundo SL ahorrado seguido (PPA 135); el filtro cuida la cuenta aunque no se vea.
A6: 46311 | B6: Semilla | C6: =K5+L5 -> 524.28 | D6: TP | E6: SELL | K6: =Tabla13[[#This Row],[Balance Inicial ]]+Tabla13[[#This Row],[Estrategia]]+Tabla13[[#This Row],[Ajuste 1]]+Tabla13[[#This Row],[Ajuste 2]]+Tabla13[[#This Row],[Ajuste 3]]+Tabla13[[#This Row],[Ajuste 4]] -> 524.28 | M6: =(Tabla13[[#This Row],[Estrategia]]+Tabla13[[#This Row],[Ajuste 1]]+Tabla13[[#This Row],[Ajuste 2]]+Tabla13[[#This Row],[Ajuste 3]]+Tabla13[[#This Row],[Ajuste 4]])/Tabla13[[#This Row],[Balance Inicial ]]*100 -> 0 | N6: =Tabla13[[#This Row],[% día]]+N5 -> 0.82 | O6: PA 59, TP | P6: La regla se juzga en la serie, no en un día: PA 59 dejó fuera un TP que corrió hasta 1:4 y aun así se respeta el filtro.
A7: 46314 | B7: Semilla | C7: =K6+L6 -> 524.28 | D7: SL | E7: SELL | F7: -5.73 | G7: 0 | H7: 0 | K7: =Tabla13[[#This Row],[Balance Inicial ]]+Tabla13[[#This Row],[Estrategia]]+Tabla13[[#This Row],[Ajuste 1]]+Tabla13[[#This Row],[Ajuste 2]]+Tabla13[[#This Row],[Ajuste 3]]+Tabla13[[#This Row],[Ajuste 4]] -> 518.55 | M7: =(Tabla13[[#This Row],[Estrategia]]+Tabla13[[#This Row],[Ajuste 1]]+Tabla13[[#This Row],[Ajuste 2]]+Tabla13[[#This Row],[Ajuste 3]]+Tabla13[[#This Row],[Ajuste 4]])/Tabla13[[#This Row],[Balance Inicial ]]*100 -> -1.0929274 | N7: =Tabla13[[#This Row],[% día]]+N6 -> -0.27292744 | O7: Apertura con ruido en compra, se abre la venta pero se devuelve el precio, tranquilo sin expectativa, se hacen ajustes quedan todos en protección en el retroceso de la vela | P7: Operar sin expectativa: si el precio se devuelve, proteger en el retroceso de la vela y aceptar la pérdida controlada.
A8: 46315 | B8: Semilla | C8: =K7+L7 -> 518.55 | D8: TP | E8: SELL | G8: 0 | H8: -1.96 | I8: 2.5 | K8: =Tabla13[[#This Row],[Balance Inicial ]]+Tabla13[[#This Row],[Estrategia]]+Tabla13[[#This Row],[Ajuste 1]]+Tabla13[[#This Row],[Ajuste 2]]+Tabla13[[#This Row],[Ajuste 3]]+Tabla13[[#This Row],[Ajuste 4]] -> 519.09 | M8: =(Tabla13[[#This Row],[Estrategia]]+Tabla13[[#This Row],[Ajuste 1]]+Tabla13[[#This Row],[Ajuste 2]]+Tabla13[[#This Row],[Ajuste 3]]+Tabla13[[#This Row],[Ajuste 4]])/Tabla13[[#This Row],[Balance Inicial ]]*100 -> 0.10413653 | N8: =Tabla13[[#This Row],[% día]]+N7 -> -0.16879091 | O8: PPA 141, se hacen 3 ajustes, por impulso se hace el tercero aunque se gano esa ultima debo respetar que maximo 2 operaciones, se hay estrategia un ajuste sino maximo 2 ajustes diarios (DISCIPLINA) | P8: Ganar por impulso no es disciplina: el tercer ajuste salió positivo, pero el límite de 2 ajustes no se negocia.
A9: 46316 | B9: Semilla | C9: =K8+L8 -> 519.09 | D9: SL | E9: BUY | G9: 0 | H9: 0.95 | K9: =Tabla13[[#This Row],[Balance Inicial ]]+Tabla13[[#This Row],[Estrategia]]+Tabla13[[#This Row],[Ajuste 1]]+Tabla13[[#This Row],[Ajuste 2]]+Tabla13[[#This Row],[Ajuste 3]]+Tabla13[[#This Row],[Ajuste 4]] -> 520.04 | M9: =(Tabla13[[#This Row],[Estrategia]]+Tabla13[[#This Row],[Ajuste 1]]+Tabla13[[#This Row],[Ajuste 2]]+Tabla13[[#This Row],[Ajuste 3]]+Tabla13[[#This Row],[Ajuste 4]])/Tabla13[[#This Row],[Balance Inicial ]]*100 -> 0.18301258 | N9: =Tabla13[[#This Row],[% día]] -> 0.18301258 | O9: PA 56, No se ingresa por reglas, se hace los ajustes correspondientes | P9: Respeto mi filtro y cuido mi capital: esperar también es operar con inteligencia.

Sheet Metas
A1: Fecha | B1: Dia Semana | C1: Dia Comienzo Meta | D1: Ratio | E1: Etapa | F1: % Op. Etapa | G1: % Esperado | H1: % Planeado | I1: Noticia | J1: Nota
A2: 46317 | B2: =UPPER(TEXT(A2,"dddd")) -> JUEVES | C2: 16 | D2: =_xlfn.XLOOKUP(Tabla3[[#This Row],[Dia Semana]],Riesgo!A:A,Riesgo!B:B) -> 2 | E2: Semilla | F2: =_xlfn.XLOOKUP(Tabla3[[#This Row],[Etapa]],Etapas!A:A,Etapas!B:B) -> 0.02 | G2: =Tabla3[[#This Row],[% Op. Etapa]]*Tabla3[[#This Row],[Ratio]] -> 0.04 | H2: =IF(Tabla3[[#This Row],[Noticia]]>0,Tabla3[[#This Row],[% Esperado]]/2,Tabla3[[#This Row],[% Esperado]]) -> 0.04 | I2: 0
A3: 46318 | B3: =UPPER(TEXT(A3,"dddd")) -> VIERNES | C3: 17 | D3: =_xlfn.XLOOKUP(Tabla3[[#This Row],[Dia Semana]],Riesgo!A:A,Riesgo!B:B) -> 1 | E3: Semilla | F3: =_xlfn.XLOOKUP(Tabla3[[#This Row],[Etapa]],Etapas!A:A,Etapas!B:B) -> 0.02 | G3: =Tabla3[[#This Row],[% Op. Etapa]]*Tabla3[[#This Row],[Ratio]] -> 0.02 | H3: =IF(Tabla3[[#This Row],[Noticia]]>0,Tabla3[[#This Row],[% Esperado]]/2,Tabla3[[#This Row],[% Esperado]]) -> 0.02 | I3: 0
A4: 46319 | B4: =UPPER(TEXT(A4,"dddd")) -> SÁBADO | C4: 18 | D4: =_xlfn.XLOOKUP(Tabla3[[#This Row],[Dia Semana]],Riesgo!A:A,Riesgo!B:B) -> 0 | E4: Semilla | F4: =_xlfn.XLOOKUP(Tabla3[[#This Row],[Etapa]],Etapas!A:A,Etapas!B:B) -> 0.02 | G4: =Tabla3[[#This Row],[% Op. Etapa]]*Tabla3[[#This Row],[Ratio]] -> 0 | H4: =IF(Tabla3[[#This Row],[Noticia]]>0,Tabla3[[#This Row],[% Esperado]]/2,Tabla3[[#This Row],[% Esperado]]) -> 0 | I4: 0
A5: 46320 | B5: =UPPER(TEXT(A5,"dddd")) -> DOMINGO | C5: 19 | D5: =_xlfn.XLOOKUP(Tabla3[[#This Row],[Dia Semana]],Riesgo!A:A,Riesgo!B:B) -> 0 | E5: Semilla | F5: =_xlfn.XLOOKUP(Tabla3[[#This Row],[Etapa]],Etapas!A:A,Etapas!B:B) -> 0.02 | G5: =Tabla3[[#This Row],[% Op. Etapa]]*Tabla3[[#This Row],[Ratio]] -> 0 | H5: =IF(Tabla3[[#This Row],[Noticia]]>0,Tabla3[[#This Row],[% Esperado]]/2,Tabla3[[#This Row],[% Esperado]]) -> 0 | I5: 0
A6: 46321 | B6: =UPPER(TEXT(A6,"dddd")) -> LUNES | C6: 20 | D6: =_xlfn.XLOOKUP(Tabla3[[#This Row],[Dia Semana]],Riesgo!A:A,Riesgo!B:B) -> 2 | E6: Semilla | F6: =_xlfn.XLOOKUP(Tabla3[[#This Row],[Etapa]],Etapas!A:A,Etapas!B:B) -> 0.02 | G6: =Tabla3[[#This Row],[% Op. Etapa]]*Tabla3[[#This Row],[Ratio]] -> 0.04 | H6: =IF(Tabla3[[#This Row],[Noticia]]>0,Tabla3[[#This Row],[% Esperado]]/2,Tabla3[[#This Row],[% Esperado]]) -> 0.04 | I6: 0
A7: 46322 | B7: =UPPER(TEXT(A7,"dddd")) -> MARTES | C7: 21 | D7: =_xlfn.XLOOKUP(Tabla3[[#This Row],[Dia Semana]],Riesgo!A:A,Riesgo!B:B) -> 2 | E7: Semilla | F7: =_xlfn.XLOOKUP(Tabla3[[#This Row],[Etapa]],Etapas!A:A,Etapas!B:B) -> 0.02 | G7: =Tabla3[[#This Row],[% Op. Etapa]]*Tabla3[[#This Row],[Ratio]] -> 0.04 | H7: =IF(Tabla3[[#This Row],[Noticia]]>0,Tabla3[[#This Row],[% Esperado]]/2,Tabla3[[#This Row],[% Esperado]]) -> 0.04 | I7: 0
A8: 46323 | B8: =UPPER(TEXT(A8,"dddd")) -> MIÉRCOLES | C8: 22 | D8: =_xlfn.XLOOKUP(Tabla3[[#This Row],[Dia Semana]],Riesgo!A:A,Riesgo!B:B) -> 1 | E8: Semilla | F8: =_xlfn.XLOOKUP(Tabla3[[#This Row],[Etapa]],Etapas!A:A,Etapas!B:B) -> 0.02 | G8: =Tabla3[[#This Row],[% Op. Etapa]]*Tabla3[[#This Row],[Ratio]] -> 0.02 | H8: =IF(Tabla3[[#This Row],[Noticia]]>0,Tabla3[[#This Row],[% Esperado]]/2,Tabla3[[#This Row],[% Esperado]]) -> 0.01 | I8: 1 | J8: 13:00 Federal Funds Rate, FOMC Statement, FOMC Press Conference
A9: 46324 | B9: =UPPER(TEXT(A9,"dddd")) -> JUEVES | C9: 23 | D9: =_xlfn.XLOOKUP(Tabla3[[#This Row],[Dia Semana]],Riesgo!A:A,Riesgo!B:B) -> 2 | E9: Semilla | F9: =_xlfn.XLOOKUP(Tabla3[[#This Row],[Etapa]],Etapas!A:A,Etapas!B:B) -> 0.02 | G9: =Tabla3[[#This Row],[% Op. Etapa]]*Tabla3[[#This Row],[Ratio]] -> 0.04 | H9: =IF(Tabla3[[#This Row],[Noticia]]>0,Tabla3[[#This Row],[% Esperado]]/2,Tabla3[[#This Row],[% Esperado]]) -> 0.02 | I9: 1 | J9: 07:30 Advance GDP q/q, Core PCE Price Index m/m
A10: 46325 | B10: =UPPER(TEXT(A10,"dddd")) -> VIERNES | C10: 24 | D10: =_xlfn.XLOOKUP(Tabla3[[#This Row],[Dia Semana]],Riesgo!A:A,Riesgo!B:B) -> 1 | E10: Semilla | F10: =_xlfn.XLOOKUP(Tabla3[[#This Row],[Etapa]],Etapas!A:A,Etapas!B:B) -> 0.02 | G10: =Tabla3[[#This Row],[% Op. Etapa]]*Tabla3[[#This Row],[Ratio]] -> 0.02 | H10: =IF(Tabla3[[#This Row],[Noticia]]>0,Tabla3[[#This Row],[% Esperado]]/2,Tabla3[[#This Row],[% Esperado]]) -> 0.02 | I10: 0
A11: 46326 | B11: =UPPER(TEXT(A11,"dddd")) -> SÁBADO | C11: 25 | D11: =_xlfn.XLOOKUP(Tabla3[[#This Row],[Dia Semana]],Riesgo!A:A,Riesgo!B:B) -> 0 | E11: Semilla | F11: =_xlfn.XLOOKUP(Tabla3[[#This Row],[Etapa]],Etapas!A:A,Etapas!B:B) -> 0.02 | G11: =Tabla3[[#This Row],[% Op. Etapa]]*Tabla3[[#This Row],[Ratio]] -> 0 | H11: =IF(Tabla3[[#This Row],[Noticia]]>0,Tabla3[[#This Row],[% Esperado]]/2,Tabla3[[#This Row],[% Esperado]]) -> 0 | I11: 0
A12: 46327 | B12: =UPPER(TEXT(A12,"dddd")) -> DOMINGO | C12: 26 | D12: =_xlfn.XLOOKUP(Tabla3[[#This Row],[Dia Semana]],Riesgo!A:A,Riesgo!B:B) -> 0 | E12: Semilla | F12: =_xlfn.XLOOKUP(Tabla3[[#This Row],[Etapa]],Etapas!A:A,Etapas!B:B) -> 0.02 | G12: =Tabla3[[#This Row],[% Op. Etapa]]*Tabla3[[#This Row],[Ratio]] -> 0 | H12: =IF(Tabla3[[#This Row],[Noticia]]>0,Tabla3[[#This Row],[% Esperado]]/2,Tabla3[[#This Row],[% Esperado]]) -> 0 | I12: 0
A13: 46328 | B13: =UPPER(TEXT(A13,"dddd")) -> LUNES | C13: 27 | D13: =_xlfn.XLOOKUP(Tabla3[[#This Row],[Dia Semana]],Riesgo!A:A,Riesgo!B:B) -> 2 | E13: Semilla | F13: =_xlfn.XLOOKUP(Tabla3[[#This Row],[Etapa]],Etapas!A:A,Etapas!B:B) -> 0.02 | G13: =Tabla3[[#This Row],[% Op. Etapa]]*Tabla3[[#This Row],[Ratio]] -> 0.04 | H13: =IF(Tabla3[[#This Row],[Noticia]]>0,Tabla3[[#This Row],[% Esperado]]/2,Tabla3[[#This Row],[% Esperado]]) -> 0.04 | I13: 0
A14: 46329 | B14: =UPPER(TEXT(A14,"dddd")) -> MARTES | C14: 28 | D14: =_xlfn.XLOOKUP(Tabla3[[#This Row],[Dia Semana]],Riesgo!A:A,Riesgo!B:B) -> 2 | E14: Semilla | F14: =_xlfn.XLOOKUP(Tabla3[[#This Row],[Etapa]],Etapas!A:A,Etapas!B:B) -> 0.02 | G14: =Tabla3[[#This Row],[% Op. Etapa]]*Tabla3[[#This Row],[Ratio]] -> 0.04 | H14: =IF(Tabla3[[#This Row],[Noticia]]>0,Tabla3[[#This Row],[% Esperado]]/2,Tabla3[[#This Row],[% Esperado]]) -> 0.02 | I14: 1 | J14: Congressional Elections
A15: 46330 | B15: =UPPER(TEXT(A15,"dddd")) -> MIÉRCOLES | C15: 29 | D15: =_xlfn.XLOOKUP(Tabla3[[#This Row],[Dia Semana]],Riesgo!A:A,Riesgo!B:B) -> 1 | E15: Semilla | F15: =_xlfn.XLOOKUP(Tabla3[[#This Row],[Etapa]],Etapas!A:A,Etapas!B:B) -> 0.02 | G15: =Tabla3[[#This Row],[% Op. Etapa]]*Tabla3[[#This Row],[Ratio]] -> 0.02 | H15: =IF(Tabla3[[#This Row],[Noticia]]>0,Tabla3[[#This Row],[% Esperado]]/2,Tabla3[[#This Row],[% Esperado]]) -> 0.02 | I15: 0
A16: 46331 | B16: =UPPER(TEXT(A16,"dddd")) -> JUEVES | C16: 30 | D16: =_xlfn.XLOOKUP(Tabla3[[#This Row],[Dia Semana]],Riesgo!A:A,Riesgo!B:B) -> 2 | E16: Semilla | F16: =_xlfn.XLOOKUP(Tabla3[[#This Row],[Etapa]],Etapas!A:A,Etapas!B:B) -> 0.02 | G16: =Tabla3[[#This Row],[% Op. Etapa]]*Tabla3[[#This Row],[Ratio]] -> 0.04 | H16: =IF(Tabla3[[#This Row],[Noticia]]>0,Tabla3[[#This Row],[% Esperado]]/2,Tabla3[[#This Row],[% Esperado]]) -> 0.04 | I16: 0
A17: 46332 | B17: =UPPER(TEXT(A17,"dddd")) -> VIERNES | C17: 31 | D17: =_xlfn.XLOOKUP(Tabla3[[#This Row],[Dia Semana]],Riesgo!A:A,Riesgo!B:B) -> 1 | E17: Incubación | F17: =_xlfn.XLOOKUP(Tabla3[[#This Row],[Etapa]],Etapas!A:A,Etapas!B:B) -> 0.005 | G17: =Tabla3[[#This Row],[% Op. Etapa]]*Tabla3[[#This Row],[Ratio]] -> 0.005 | H17: =IF(Tabla3[[#This Row],[Noticia]]>0,Tabla3[[#This Row],[% Esperado]]/2,Tabla3[[#This Row],[% Esperado]]) -> 0.0025 | I17: 1 | J17: 08:30 Average Hourly Earnings m/m, Non-Farm Employment Change, Unemployment Rate
A18: 46333 | B18: =UPPER(TEXT(A18,"dddd")) -> SÁBADO | C18: 32 | D18: =_xlfn.XLOOKUP(Tabla3[[#This Row],[Dia Semana]],Riesgo!A:A,Riesgo!B:B) -> 0 | E18: Incubación | F18: =_xlfn.XLOOKUP(Tabla3[[#This Row],[Etapa]],Etapas!A:A,Etapas!B:B) -> 0.005 | G18: =Tabla3[[#This Row],[% Op. Etapa]]*Tabla3[[#This Row],[Ratio]] -> 0 | H18: =IF(Tabla3[[#This Row],[Noticia]]>0,Tabla3[[#This Row],[% Esperado]]/2,Tabla3[[#This Row],[% Esperado]]) -> 0 | I18: 0
A19: 46334 | B19: =UPPER(TEXT(A19,"dddd")) -> DOMINGO | C19: 33 | D19: =_xlfn.XLOOKUP(Tabla3[[#This Row],[Dia Semana]],Riesgo!A:A,Riesgo!B:B) -> 0 | E19: Incubación | F19: =_xlfn.XLOOKUP(Tabla3[[#This Row],[Etapa]],Etapas!A:A,Etapas!B:B) -> 0.005 | G19: =Tabla3[[#This Row],[% Op. Etapa]]*Tabla3[[#This Row],[Ratio]] -> 0 | H19: =IF(Tabla3[[#This Row],[Noticia]]>0,Tabla3[[#This Row],[% Esperado]]/2,Tabla3[[#This Row],[% Esperado]]) -> 0 | I19: 0
A20: 46335 | B20: =UPPER(TEXT(A20,"dddd")) -> LUNES | C20: 34 | D20: =_xlfn.XLOOKUP(Tabla3[[#This Row],[Dia Semana]],Riesgo!A:A,Riesgo!B:B) -> 2 | E20: Incubación | F20: =_xlfn.XLOOKUP(Tabla3[[#This Row],[Etapa]],Etapas!A:A,Etapas!B:B) -> 0.005 | G20: =Tabla3[[#This Row],[% Op. Etapa]]*Tabla3[[#This Row],[Ratio]] -> 0.01 | H20: =IF(Tabla3[[#This Row],[Noticia]]>0,Tabla3[[#This Row],[% Esperado]]/2,Tabla3[[#This Row],[% Esperado]]) -> 0.01 | I20: 0
A21: 46336 | B21: =UPPER(TEXT(A21,"dddd")) -> MARTES | C21: 35 | D21: =_xlfn.XLOOKUP(Tabla3[[#This Row],[Dia Semana]],Riesgo!A:A,Riesgo!B:B) -> 2 | E21: Incubación | F21: =_xlfn.XLOOKUP(Tabla3[[#This Row],[Etapa]],Etapas!A:A,Etapas!B:B) -> 0.005 | G21: =Tabla3[[#This Row],[% Op. Etapa]]*Tabla3[[#This Row],[Ratio]] -> 0.01 | H21: =IF(Tabla3[[#This Row],[Noticia]]>0,Tabla3[[#This Row],[% Esperado]]/2,Tabla3[[#This Row],[% Esperado]]) -> 0.005 | I21: 1 | J21: 8:30 Core CPI m/m, Core CPI y/y, CPI m/m, CPI y/y
A22: 46337 | B22: =UPPER(TEXT(A22,"dddd")) -> MIÉRCOLES | C22: 36 | D22: =_xlfn.XLOOKUP(Tabla3[[#This Row],[Dia Semana]],Riesgo!A:A,Riesgo!B:B) -> 1 | E22: Incubación | F22: =_xlfn.XLOOKUP(Tabla3[[#This Row],[Etapa]],Etapas!A:A,Etapas!B:B) -> 0.005 | G22: =Tabla3[[#This Row],[% Op. Etapa]]*Tabla3[[#This Row],[Ratio]] -> 0.005 | H22: =IF(Tabla3[[#This Row],[Noticia]]>0,Tabla3[[#This Row],[% Esperado]]/2,Tabla3[[#This Row],[% Esperado]]) -> 0.0025 | I22: 1 | J22: Bank Holiday
A23: 46338 | B23: =UPPER(TEXT(A23,"dddd")) -> JUEVES | C23: 37 | D23: =_xlfn.XLOOKUP(Tabla3[[#This Row],[Dia Semana]],Riesgo!A:A,Riesgo!B:B) -> 2 | E23: Incubación | F23: =_xlfn.XLOOKUP(Tabla3[[#This Row],[Etapa]],Etapas!A:A,Etapas!B:B) -> 0.005 | G23: =Tabla3[[#This Row],[% Op. Etapa]]*Tabla3[[#This Row],[Ratio]] -> 0.01 | H23: =IF(Tabla3[[#This Row],[Noticia]]>0,Tabla3[[#This Row],[% Esperado]]/2,Tabla3[[#This Row],[% Esperado]]) -> 0.01 | I23: 0
A24: 46339 | B24: =UPPER(TEXT(A24,"dddd")) -> VIERNES | C24: 38 | D24: =_xlfn.XLOOKUP(Tabla3[[#This Row],[Dia Semana]],Riesgo!A:A,Riesgo!B:B) -> 1 | E24: Incubación | F24: =_xlfn.XLOOKUP(Tabla3[[#This Row],[Etapa]],Etapas!A:A,Etapas!B:B) -> 0.005 | G24: =Tabla3[[#This Row],[% Op. Etapa]]*Tabla3[[#This Row],[Ratio]] -> 0.005 | H24: =IF(Tabla3[[#This Row],[Noticia]]>0,Tabla3[[#This Row],[% Esperado]]/2,Tabla3[[#This Row],[% Esperado]]) -> 0.0025 | I24: 1 | J24: 08:30 Core PPI m/m, PPI m/m
A25: 46340 | B25: =UPPER(TEXT(A25,"dddd")) -> SÁBADO | C25: 39 | D25: =_xlfn.XLOOKUP(Tabla3[[#This Row],[Dia Semana]],Riesgo!A:A,Riesgo!B:B) -> 0 | E25: Incubación | F25: =_xlfn.XLOOKUP(Tabla3[[#This Row],[Etapa]],Etapas!A:A,Etapas!B:B) -> 0.005 | G25: =Tabla3[[#This Row],[% Op. Etapa]]*Tabla3[[#This Row],[Ratio]] -> 0 | H25: =IF(Tabla3[[#This Row],[Noticia]]>0,Tabla3[[#This Row],[% Esperado]]/2,Tabla3[[#This Row],[% Esperado]]) -> 0 | I25: 0
A26: 46341 | B26: =UPPER(TEXT(A26,"dddd")) -> DOMINGO | C26: 40 | D26: =_xlfn.XLOOKUP(Tabla3[[#This Row],[Dia Semana]],Riesgo!A:A,Riesgo!B:B) -> 0 | E26: Incubación | F26: =_xlfn.XLOOKUP(Tabla3[[#This Row],[Etapa]],Etapas!A:A,Etapas!B:B) -> 0.005 | G26: =Tabla3[[#This Row],[% Op. Etapa]]*Tabla3[[#This Row],[Ratio]] -> 0 | H26: =IF(Tabla3[[#This Row],[Noticia]]>0,Tabla3[[#This Row],[% Esperado]]/2,Tabla3[[#This Row],[% Esperado]]) -> 0 | I26: 0
A27: 46342 | B27: =UPPER(TEXT(A27,"dddd")) -> LUNES | C27: 41 | D27: =_xlfn.XLOOKUP(Tabla3[[#This Row],[Dia Semana]],Riesgo!A:A,Riesgo!B:B) -> 2 | E27: Incubación | F27: =_xlfn.XLOOKUP(Tabla3[[#This Row],[Etapa]],Etapas!A:A,Etapas!B:B) -> 0.005 | G27: =Tabla3[[#This Row],[% Op. Etapa]]*Tabla3[[#This Row],[Ratio]] -> 0.01 | H27: =IF(Tabla3[[#This Row],[Noticia]]>0,Tabla3[[#This Row],[% Esperado]]/2,Tabla3[[#This Row],[% Esperado]]) -> 0.01 | I27: 0
A28: 46343 | B28: =UPPER(TEXT(A28,"dddd")) -> MARTES | C28: 42 | D28: =_xlfn.XLOOKUP(Tabla3[[#This Row],[Dia Semana]],Riesgo!A:A,Riesgo!B:B) -> 2 | E28: Incubación | F28: =_xlfn.XLOOKUP(Tabla3[[#This Row],[Etapa]],Etapas!A:A,Etapas!B:B) -> 0.005 | G28: =Tabla3[[#This Row],[% Op. Etapa]]*Tabla3[[#This Row],[Ratio]] -> 0.01 | H28: =IF(Tabla3[[#This Row],[Noticia]]>0,Tabla3[[#This Row],[% Esperado]]/2,Tabla3[[#This Row],[% Esperado]]) -> 0.005 | I28: 1 | J28: 08:30 Core Retail Sales m/m, Retail Sales m/m
A29: 46344 | B29: =UPPER(TEXT(A29,"dddd")) -> MIÉRCOLES | C29: 43 | D29: =_xlfn.XLOOKUP(Tabla3[[#This Row],[Dia Semana]],Riesgo!A:A,Riesgo!B:B) -> 1 | E29: Incubación | F29: =_xlfn.XLOOKUP(Tabla3[[#This Row],[Etapa]],Etapas!A:A,Etapas!B:B) -> 0.005 | G29: =Tabla3[[#This Row],[% Op. Etapa]]*Tabla3[[#This Row],[Ratio]] -> 0.005 | H29: =IF(Tabla3[[#This Row],[Noticia]]>0,Tabla3[[#This Row],[% Esperado]]/2,Tabla3[[#This Row],[% Esperado]]) -> 0.0025 | I29: 1 | J29: 14:00 FOMC Meeting Minutes
A30: 46345 | B30: =UPPER(TEXT(A30,"dddd")) -> JUEVES | C30: 44 | D30: =_xlfn.XLOOKUP(Tabla3[[#This Row],[Dia Semana]],Riesgo!A:A,Riesgo!B:B) -> 2 | E30: Incubación | F30: =_xlfn.XLOOKUP(Tabla3[[#This Row],[Etapa]],Etapas!A:A,Etapas!B:B) -> 0.005 | G30: =Tabla3[[#This Row],[% Op. Etapa]]*Tabla3[[#This Row],[Ratio]] -> 0.01 | H30: =IF(Tabla3[[#This Row],[Noticia]]>0,Tabla3[[#This Row],[% Esperado]]/2,Tabla3[[#This Row],[% Esperado]]) -> 0.01 | I30: 0
A31: 46346 | B31: =UPPER(TEXT(A31,"dddd")) -> VIERNES | C31: 45 | D31: =_xlfn.XLOOKUP(Tabla3[[#This Row],[Dia Semana]],Riesgo!A:A,Riesgo!B:B) -> 1 | E31: Incubación | F31: =_xlfn.XLOOKUP(Tabla3[[#This Row],[Etapa]],Etapas!A:A,Etapas!B:B) -> 0.005 | G31: =Tabla3[[#This Row],[% Op. Etapa]]*Tabla3[[#This Row],[Ratio]] -> 0.005 | H31: =IF(Tabla3[[#This Row],[Noticia]]>0,Tabla3[[#This Row],[% Esperado]]/2,Tabla3[[#This Row],[% Esperado]]) -> 0.005 | I31: 0
A32: 46347 | B32: =UPPER(TEXT(A32,"dddd")) -> SÁBADO | C32: 46 | D32: =_xlfn.XLOOKUP(Tabla3[[#This Row],[Dia Semana]],Riesgo!A:A,Riesgo!B:B) -> 0 | E32: Incubación | F32: =_xlfn.XLOOKUP(Tabla3[[#This Row],[Etapa]],Etapas!A:A,Etapas!B:B) -> 0.005 | G32: =Tabla3[[#This Row],[% Op. Etapa]]*Tabla3[[#This Row],[Ratio]] -> 0 | H32: =IF(Tabla3[[#This Row],[Noticia]]>0,Tabla3[[#This Row],[% Esperado]]/2,Tabla3[[#This Row],[% Esperado]]) -> 0 | I32: 0
A33: 46348 | B33: =UPPER(TEXT(A33,"dddd")) -> DOMINGO | C33: 47 | D33: =_xlfn.XLOOKUP(Tabla3[[#This Row],[Dia Semana]],Riesgo!A:A,Riesgo!B:B) -> 0 | E33: Incubación | F33: =_xlfn.XLOOKUP(Tabla3[[#This Row],[Etapa]],Etapas!A:A,Etapas!B:B) -> 0.005 | G33: =Tabla3[[#This Row],[% Op. Etapa]]*Tabla3[[#This Row],[Ratio]] -> 0 | H33: =IF(Tabla3[[#This Row],[Noticia]]>0,Tabla3[[#This Row],[% Esperado]]/2,Tabla3[[#This Row],[% Esperado]]) -> 0 | I33: 0
A34: 46349 | B34: =UPPER(TEXT(A34,"dddd")) -> LUNES | C34: 48 | D34: =_xlfn.XLOOKUP(Tabla3[[#This Row],[Dia Semana]],Riesgo!A:A,Riesgo!B:B) -> 2 | E34: Incubación | F34: =_xlfn.XLOOKUP(Tabla3[[#This Row],[Etapa]],Etapas!A:A,Etapas!B:B) -> 0.005 | G34: =Tabla3[[#This Row],[% Op. Etapa]]*Tabla3[[#This Row],[Ratio]] -> 0.01 | H34: =IF(Tabla3[[#This Row],[Noticia]]>0,Tabla3[[#This Row],[% Esperado]]/2,Tabla3[[#This Row],[% Esperado]]) -> 0.01 | I34: 0
A35: 46350 | B35: =UPPER(TEXT(A35,"dddd")) -> MARTES | C35: 49 | D35: =_xlfn.XLOOKUP(Tabla3[[#This Row],[Dia Semana]],Riesgo!A:A,Riesgo!B:B) -> 2 | E35: Incubación | F35: =_xlfn.XLOOKUP(Tabla3[[#This Row],[Etapa]],Etapas!A:A,Etapas!B:B) -> 0.005 | G35: =Tabla3[[#This Row],[% Op. Etapa]]*Tabla3[[#This Row],[Ratio]] -> 0.01 | H35: =IF(Tabla3[[#This Row],[Noticia]]>0,Tabla3[[#This Row],[% Esperado]]/2,Tabla3[[#This Row],[% Esperado]]) -> 0.01 | I35: 0
A36: 46351 | B36: =UPPER(TEXT(A36,"dddd")) -> MIÉRCOLES | C36: 50 | D36: =_xlfn.XLOOKUP(Tabla3[[#This Row],[Dia Semana]],Riesgo!A:A,Riesgo!B:B) -> 1 | E36: Incubación | F36: =_xlfn.XLOOKUP(Tabla3[[#This Row],[Etapa]],Etapas!A:A,Etapas!B:B) -> 0.005 | G36: =Tabla3[[#This Row],[% Op. Etapa]]*Tabla3[[#This Row],[Ratio]] -> 0.005 | H36: =IF(Tabla3[[#This Row],[Noticia]]>0,Tabla3[[#This Row],[% Esperado]]/2,Tabla3[[#This Row],[% Esperado]]) -> 0.0025 | I36: 1 | J36: 08:30 Core PCE Price Index m/m, Prelim GDP q/q
A37: 46352 | B37: =UPPER(TEXT(A37,"dddd")) -> JUEVES | C37: 51 | D37: =_xlfn.XLOOKUP(Tabla3[[#This Row],[Dia Semana]],Riesgo!A:A,Riesgo!B:B) -> 2 | E37: Incubación | F37: =_xlfn.XLOOKUP(Tabla3[[#This Row],[Etapa]],Etapas!A:A,Etapas!B:B) -> 0.005 | G37: =Tabla3[[#This Row],[% Op. Etapa]]*Tabla3[[#This Row],[Ratio]] -> 0.01 | H37: =IF(Tabla3[[#This Row],[Noticia]]>0,Tabla3[[#This Row],[% Esperado]]/2,Tabla3[[#This Row],[% Esperado]]) -> 0.005 | I37: 1 | J37: Bank Holiday
A38: 46353 | B38: =UPPER(TEXT(A38,"dddd")) -> VIERNES | C38: 52 | D38: =_xlfn.XLOOKUP(Tabla3[[#This Row],[Dia Semana]],Riesgo!A:A,Riesgo!B:B) -> 1 | E38: Incubación | F38: =_xlfn.XLOOKUP(Tabla3[[#This Row],[Etapa]],Etapas!A:A,Etapas!B:B) -> 0.005 | G38: =Tabla3[[#This Row],[% Op. Etapa]]*Tabla3[[#This Row],[Ratio]] -> 0.005 | H38: =IF(Tabla3[[#This Row],[Noticia]]>0,Tabla3[[#This Row],[% Esperado]]/2,Tabla3[[#This Row],[% Esperado]]) -> 0.005 | I38: 0
A39: 46354 | B39: =UPPER(TEXT(A39,"dddd")) -> SÁBADO | C39: 53 | D39: =_xlfn.XLOOKUP(Tabla3[[#This Row],[Dia Semana]],Riesgo!A:A,Riesgo!B:B) -> 0 | E39: Incubación | F39: =_xlfn.XLOOKUP(Tabla3[[#This Row],[Etapa]],Etapas!A:A,Etapas!B:B) -> 0.005 | G39: =Tabla3[[#This Row],[% Op. Etapa]]*Tabla3[[#This Row],[Ratio]] -> 0 | H39: =IF(Tabla3[[#This Row],[Noticia]]>0,Tabla3[[#This Row],[% Esperado]]/2,Tabla3[[#This Row],[% Esperado]]) -> 0 | I39: 0
A40: 46355 | B40: =UPPER(TEXT(A40,"dddd")) -> DOMINGO | C40: 54 | D40: =_xlfn.XLOOKUP(Tabla3[[#This Row],[Dia Semana]],Riesgo!A:A,Riesgo!B:B) -> 0 | E40: Incubación | F40: =_xlfn.XLOOKUP(Tabla3[[#This Row],[Etapa]],Etapas!A:A,Etapas!B:B) -> 0.005 | G40: =Tabla3[[#This Row],[% Op. Etapa]]*Tabla3[[#This Row],[Ratio]] -> 0 | H40: =IF(Tabla3[[#This Row],[Noticia]]>0,Tabla3[[#This Row],[% Esperado]]/2,Tabla3[[#This Row],[% Esperado]]) -> 0 | I40: 0
...

Sheet Riesgo
A1: DIA DE LA SEMANA | B1: RATIO
A2: LUNES | B2: 2
A3: MARTES | B3: 2
A4: MIÉRCOLES | B4: 1
A5: JUEVES | B5: 2
A6: VIERNES | B6: 1
A7: SÁBADO | B7: 0
A8: DOMINGO | B8: 0

Sheet Etapas
A1: Etapa | B1: % Op | C1: Dias Minimos | D1: Dias Meta | E1: Multiplicador | F1: Edge | G1: % a Ganar | H1: % Ganancias | I1: Capital Personal
A2: Semilla | B2: 0.02 | C2: 30 | D2: 30 | E2: 10 | F2: 60 | G2: 0.07 | H2: 0 | I2: $500 → $1,000
A3: Incubación | B3: 0.005 | C3: 60 | D3: 60 | E3: 10 | F3: 70 | G3: 0.07 | H3: 0.4 | I3: $1,000 → $2,000
A4: Aceleración | B4: 0.0035 | C4: 60 | D4: 60 | E4: 25 | F4: 90 | G4: 0.07 | H4: 0.5 | I4: $2,000 → $5,000
A5: Pro | B5: 0.0035 | C5: 60 | D5: 60 | E5: 40 | F5: 90 | G5: 0.07 | H5: 0.6 | I5: $5,000 → $10,000
A6: Pro 500 | B6: 0.0035 | C6: 60 | D6: 60 | E6: 50 | F6: 90 | G6: 0.07 | H6: 0.7 | I6: $10,000 → $20,000
A7: Pro M | B7: 0.0035 | C7: 0 | D7: 0 | E7: 50 | F7: 90 | G7: 0 | H7: 0.8 | I7: $20,000 → $1,000,000
